Traceback (most recent call last):
  File "C:\Users\jonsh\AppData\Local\Packages\PythonSoftwareFoundation.Python.3.9_qbz5n2kfra8p0\LocalCache\local-packages\Python39\site-packages\jupyter_cache\executors\utils.py", line 51, in single_nb_execution
    executenb(
  File "C:\Users\jonsh\AppData\Local\Packages\PythonSoftwareFoundation.Python.3.9_qbz5n2kfra8p0\LocalCache\local-packages\Python39\site-packages\nbclient\client.py", line 1204, in execute
    return NotebookClient(nb=nb, resources=resources, km=km, **kwargs).execute()
  File "C:\Users\jonsh\AppData\Local\Packages\PythonSoftwareFoundation.Python.3.9_qbz5n2kfra8p0\LocalCache\local-packages\Python39\site-packages\nbclient\util.py", line 84, in wrapped
    return just_run(coro(*args, **kwargs))
  File "C:\Users\jonsh\AppData\Local\Packages\PythonSoftwareFoundation.Python.3.9_qbz5n2kfra8p0\LocalCache\local-packages\Python39\site-packages\nbclient\util.py", line 62, in just_run
    return loop.run_until_complete(coro)
  File "C:\Program Files\WindowsApps\PythonSoftwareFoundation.Python.3.9_3.9.3568.0_x64__qbz5n2kfra8p0\lib\asyncio\base_events.py", line 647, in run_until_complete
    return future.result()
  File "C:\Users\jonsh\AppData\Local\Packages\PythonSoftwareFoundation.Python.3.9_qbz5n2kfra8p0\LocalCache\local-packages\Python39\site-packages\nbclient\client.py", line 663, in async_execute
    await self.async_execute_cell(
  File "C:\Users\jonsh\AppData\Local\Packages\PythonSoftwareFoundation.Python.3.9_qbz5n2kfra8p0\LocalCache\local-packages\Python39\site-packages\nbclient\client.py", line 965, in async_execute_cell
    await self._check_raise_for_error(cell, cell_index, exec_reply)
  File "C:\Users\jonsh\AppData\Local\Packages\PythonSoftwareFoundation.Python.3.9_qbz5n2kfra8p0\LocalCache\local-packages\Python39\site-packages\nbclient\client.py", line 862, in _check_raise_for_error
    raise CellExecutionError.from_cell_and_msg(cell, exec_reply_content)
nbclient.exceptions.CellExecutionError: An error occurred while executing the following cell:
------------------
import numpy as np
import matplotlib.pyplot as plt
from myst_nb import glue

# Consistent system
x = np.linspace(0, 4, 200)
y2 = 3 - x
y1 = -1 + x

fig, ax = plt.subplots(figsize=(8, 6))
plt.plot(x, y1, label="$x_1 + x_2 = 3$")
plt.plot(x, y2, label="$x_1 - x_2 = 1$")
plt.plot(2, 1, "ko")
plt.axis([0, 4, 0, 4])
plt.xlabel("$x_1$", fontsize=16)
plt.ylabel("$x_2$", fontsize=16)
plt.legend(fontsize=14)
plt.show()

glue("consistent_system_plot", fig, display=False)

# Inonsistent system
y1 = x + 1
y2 = x - 1

fig, ax = plt.subplots(figsize=(8, 6))
plt.plot(x, y1, label="$x_1 - x_2 = -1$")
plt.plot(x, y2, label="$x_1 - x_2 = 1$")
plt.axis([0, 4, 0, 4])
plt.xlabel("$x_1$", fontsize=16)
plt.ylabel("$x_2$", fontsize=16)
plt.legend(fontsize=14)
plt.show()

glue("inconsistent_system_plot", fig, display=False)

# indeterminate system
y1 = x + 1
y2 = (2 * x + 2) / 2

fig, ax = plt.subplots(figsize=(8, 6))
plt.plot(x, y1, label="$x_1 - x_2 = 1$")
plt.plot(x, y2, label="$2x_1 - 2x_2 = 2$")
plt.axis([0, 4, 0, 4])
plt.xlabel("$x_1$", fontsize=16)
plt.ylabel("$x_2$", fontsize=16)
plt.legend(fontsize=14)
plt.show()

glue("indeterminate_system_plot", fig, display=False)
------------------

[1;31m---------------------------------------------------------------------------[0m
[1;31mModuleNotFoundError[0m                       Traceback (most recent call last)
Cell [1;32mIn [2], line 1[0m
[1;32m----> 1[0m [38;5;28;01mimport[39;00m [38;5;21;01mnumpy[39;00m [38;5;28;01mas[39;00m [38;5;21;01mnp[39;00m
[0;32m      2[0m [38;5;28;01mimport[39;00m [38;5;21;01mmatplotlib[39;00m[38;5;21;01m.[39;00m[38;5;21;01mpyplot[39;00m [38;5;28;01mas[39;00m [38;5;21;01mplt[39;00m
[0;32m      3[0m [38;5;28;01mfrom[39;00m [38;5;21;01mmyst_nb[39;00m [38;5;28;01mimport[39;00m glue

[1;31mModuleNotFoundError[0m: No module named 'numpy'
ModuleNotFoundError: No module named 'numpy'

